<?xml version ="1.0"?>
<robot xmlns:xacro="http://www.ros.org/wiki/xacro">

    <xacro:macro name="wheel_joint" params="prefix x y z">
        <joint name="${prefix}_wheel_joint" type="continuous">
            <parent link="base_link"/>
            <child link="${prefix}_wheel_link"/>
            <origin xyz="${x} ${y} ${z}" rpy="0 0 0"/>
            <axis xyz="0 1 0"/>
        </joint>
    </xacro:macro>

    <xacro:macro name = "box_inertia" params = "m l w h xyz rpy">
        <inertial>
            <origin xyz = "${xyz}" rpy = "${rpy}" />
            <mass value = "${m}" />
            <inertia ixx = "${(m/12) * (l*l+h*h)}" ixy = "0" ixz = "0"
            iyy = "${(m/12) * (l*l+h*h)}" iyz = "0"
            izz = "${(m/12) * (l*l+h*h)}"/>
        </inertial>
    </xacro:macro>

    <xacro:macro name = "wheel_inertia" params = "m r h xyz rpy">
        <inertial>
            <origin xyz = "${xyz}" rpy = "${rpy}" />
            <mass value = "${m}" />
            <inertia ixx = "${(m/12) * (3*r*r + h*h)}" ixy = "0" ixz = "0"
            iyy = "${(m/12) * (3*r*r + h*h)}" iyz = "0"
            izz = "${(m/12) * (3*r*r + h*h)}"/>
        </inertial>
    </xacro:macro>

    <xacro:macro name="sphere_inertia" params="m r xyz rpy">
    <inertial>
        <origin xyz="${xyz}" rpy="${rpy}"/>
        <mass value="${m}"/>
        <inertia 
            ixx="${(2 * m * r * r) / 5.0}" ixy="0" ixz="0" 
            iyy="${(2 * m * r * r) / 5.0}" iyz="0" 
            izz="${(2 * m * r * r) / 5.0}"/>
    </inertial>
</xacro:macro>


</robot>
