<?xml version ="1.0"?>
<robot xmlns:xacro="http://www.ros.org/wiki/xacro">
    <xacro:macro name="wheel_link" params="prefix">
        <link name="${prefix}_wheel_link">
            <visual>
                <geometry>
                    <cylinder radius="${wheel_radius}" length="${wheel_lenght}"/>
                </geometry>
                <origin xyz="0 0 0" rpy="1.5708 0 0"/> <!-- pi/2 ≈ 1.5708 -->
                <material name="grey"/>
            </visual>
            <collision>
                <geometry>
                    <cylinder radius="${wheel_radius}" length="${wheel_lenght}"/>
                </geometry>
                <origin xyz="0 0 0" rpy="1.5708 0 0"/> <!-- pi/2 ≈ 1.5708 -->
            </collision>
            <xacro:wheel_inertia m = "1.0" r = "${wheel_radius}" h = "${wheel_lenght}" xyz="0 0 0" rpy="1.5708 0 0"/>
        </link>
    </xacro:macro>

    <xacro:macro name="wheel_joint" params="prefix x y z">
        <joint name="${prefix}_wheel_joint" type="continuous">
            <parent link="base_link"/>
            <child link="${prefix}_wheel_link"/>
            <origin xyz="${x} ${y} ${z}" rpy="0 0 0"/>
            <axis xyz="0 1 0"/>
        </joint>
    </xacro:macro>

    <xacro:macro name = "box_inertia" params = "m l w h xyz rpy">
        <inertial>
            <origin xyz = "${xyz}" rpy = "${rpy}" />
            <mass value = "${m}" />
            <inertia ixx = "${(m/12) * (l*l+h*h)}" ixy = "0" ixz = "0"
            iyy = "${(m/12) * (l*l+h*h)}" iyz = "0"
            izz = "${(m*r*r)/2}"/>
        </inertial>
    </xacro:macro>

    <xacro:macro name = "wheel_inertia" params = "m r h xyz rpy">
        <inertial>
            <origin xyz = "${xyz}" rpy = "${rpy}" />
            <mass value = "${m}" />
            <inertia ixx = "${(m/12) * (3*r*r + h*h)}" ixy = "0" ixz = "0"
            iyy = "${(m/12) * (3*r*r + h*h)}" iyz = "0"
            izz = "${(m/12) * (3*r*r + h*h)}"/>
        </inertial>
    </xacro:macro>

    <xacro:macro name = "sphere_inertia" params = "m r xyz rpy">
        <inertia>
            <origin xyz = "${xyz}" rpy = "${rpy}" />
            <mass value = "${m}" />
            <inertia ixx = "(2*m*r*r)/5" ixy = "0" ixz = "0"
            iyy= "(2*m*r*r)/5" iyz = "0"
            izz = "(2*m*r*r)/5"/> 
        </inertia>
    </xacro:macro>

</robot>
